<?xml version="1.0" encoding="utf-8"?>
<robot xmlns:xacro="http://www.ros.org/wiki/xacro" name="rmitbot">

  <link name="base_footprint"/>

  <joint name="base_link_joint" type="fixed">
    <origin xyz="0 0 0.13" rpy="0 0 0"/>
    <parent link="base_footprint"/>
    <child link="base_link"/>
  </joint>

  <link name="base_link">
  
    <inertial>
      <origin xyz="-0.000102575363615826 1.27899910523643E-07 -0.048103018145246" rpy="0 0 0" />      
      <mass value="9.21834292006588" />
      <inertia
        ixx="0.0860803865758353"
        ixy="-7.67623608449202E-19"
        ixz="7.34761264691378E-19"
        iyy="0.076812301624389"
        iyz="-1.09764490968175E-18"
        izz="0.136212310100817" />
    </inertial>

    <visual>
      <origin xyz="0 0 -0.096" rpy="0 0 0" />
      <geometry>
        <mesh filename="package://rmitbot/meshes/base_footprint.STL" />
      </geometry>
      <material name="chassis_color">
        <color rgba="0.79216 0.81961 0.93333 1" />
      </material>
    </visual>

    <collision>
      <origin xyz="0 0 0" rpy="0 0 0" />
      <geometry>
        <mesh filename="package://rmitbot/meshes/base_footprint.STL" />
      </geometry>
    </collision>

  </link>

  <link name="front_left_wheel">
    <inertial>
      <origin xyz="0 -0.021981 -1.3878E-17" rpy="0 0 0" />
      <mass value="0.32433" />
      <inertia
        ixx="0.00024356" ixy="-7.0365E-23" ixz="-3.468E-20"
        iyy="0.00038242" iyz="-4.7696E-21" izz="0.00024356" />
    </inertial>
    <visual>
      <origin xyz="0 0 0" rpy="0 0 0" />
      <geometry>
        <mesh filename="package://rmitbot/meshes/front_left_wheel.STL" />
      </geometry>
      <material name="wheel_white">
        <color rgba="1 1 1 1" />
      </material>
    </visual>
    <collision>
      <origin xyz="0 0 0" rpy="0 0 0" />
      <geometry>
        <mesh filename="package://rmitbot/meshes/front_left_wheel.STL" />
      </geometry>
    </collision>
  </link>

  <joint name="front_left_wheel_joint" type="continuous">
    <origin xyz="0.125 0.195 -0.08" rpy="0 0 0" />
    <parent link="base_link" />
    <child link="front_left_wheel" />
    <axis xyz="0 1 0" />
    <dynamics damping="0.2" />
  </joint>

  <link name="front_right_wheel">
    <inertial>
      <origin xyz="0 0.021981 0" rpy="0 0 0" />
      <mass value="0.32433" />
      <inertia
        ixx="0.00024356" ixy="4.4151E-23" ixz="3.3128E-23"
        iyy="0.00038242" iyz="-1.002E-20" izz="0.00024356" />
    </inertial>
    <visual>
      <origin xyz="0 0 0" rpy="0 0 0" />
      <geometry>
        <mesh filename="package://rmitbot/meshes/front_right_wheel.STL" />
      </geometry>
      <material name="wheel_white"/>
    </visual>
    <collision>
      <origin xyz="0 0 0" rpy="0 0 0" />
      <geometry>
        <mesh filename="package://rmitbot/meshes/front_right_wheel.STL" />
      </geometry>
    </collision>
  </link>

  <joint name="front_right_wheel_joint" type="continuous">
    <origin xyz="0.125 -0.195 -0.08" rpy="0 0 0" />
    <parent link="base_link" />
    <child link="front_right_wheel" />
    <axis xyz="0 1 0" />
    <dynamics damping="0.2" />
  </joint>

  <link name="rear_left_wheel">
    <inertial>
      <origin xyz="0 -0.021981 0" rpy="0 0 0" />
      <mass value="0.32433" />
      <inertia
        ixx="0.00024356" ixy="2.4613E-21" ixz="1.3091E-20"
        iyy="0.00038242" iyz="2.4994E-23" izz="0.00024356" />
    </inertial>
    <visual>
      <origin xyz="0 0 0" rpy="0 0 0" />
      <geometry>
        <mesh filename="package://rmitbot/meshes/rear_left_wheel.STL" />
      </geometry>
      <material name="chassis_color"/>
    </visual>
    <collision>
      <origin xyz="0 0 0" rpy="0 0 0" />
      <geometry>
        <mesh filename="package://rmitbot/meshes/rear_left_wheel.STL" />
      </geometry>
    </collision>
  </link>

  <joint name="rear_left_wheel_joint" type="continuous">
    <origin xyz="-0.125 0.195 -0.08" rpy="0 0 0" />
    <parent link="base_link" />
    <child link="rear_left_wheel" />
    <axis xyz="0 1 0" />
    <dynamics damping="0.2" />
  </joint>

  <link name="rear_right_wheel">
    <inertial>
      <origin xyz="0 0.021981 0" rpy="0 0 0" />
      <mass value="0.32433" />
      <inertia
        ixx="0.00024356" ixy="-2.3748E-21" ixz="-2.4754E-20"
        iyy="0.00038242" iyz="9.7442E-21" izz="0.00024356" />
    </inertial>
    <visual>
      <origin xyz="0 0 0" rpy="0 0 0" />
      <geometry>
        <mesh filename="package://rmitbot/meshes/rear_right_wheel.STL" />
      </geometry>
      <material name="wheel_white"/>
    </visual>
    <collision>
      <origin xyz="0 0 0" rpy="0 0 0" />
      <geometry>
        <mesh filename="package://rmitbot/meshes/rear_right_wheel.STL" />
      </geometry>
    </collision>
  </link>

  <joint name="rear_right_wheel_joint" type="continuous">
    <origin xyz="-0.125 -0.195 -0.08" rpy="0 0 0" />
    <parent link="base_link" />
    <child link="rear_right_wheel" />
    <axis xyz="0 1 0" />
    <dynamics damping="0.2" />
  </joint>

</robot>